<?xml version="1.0"?>
    <robot name="arm">

      <link name="shoulder_base">
        <visual>
          <origin xyz="0 0 .8" rpy="0 0 0" />
          <geometry>
            <sphere radius=".1" />
          </geometry>
          <material name="green">
            <color rgba="0 0 255 1" />
          </material>
        </visual>
        <collision name="base_link_collision">
          <geometry>
            <box size="0.2 0.2 0.2" />
          </geometry>
        </collision>
      </link>

      <joint name="shoulder" type="continuous">
       <origin xyz = " 0 0 .8" rpy="0 1.57 0"/>
       <parent link="shoulder_base"/>
       <child link="upper_arm"/>
       <axis xyz=" 1 1 1"/>
       <dynamics damping="0.1" />
      </joint>

      <link name="upper_arm">
      <inertial>
         <origin xyz="0 0 -.5" rpy="0 0 0"/>
         <mass value="2"/>
         <inertia ixx="1"  ixy="0"  ixz="0" iyy=".083" iyz="0" izz="1" />
       </inertial>

        <visual>
          <origin xyz="0 0 -.5" rpy="0 0 0"/>
          <geometry>
           <cylinder length="1.1" radius="0.05"/>
          </geometry>
          <material name="green">
            <color rgba="0 1 0 1" />
          </material>
        </visual>

        <collision name = "collision_upper">
          <origin xyz="0 0 -.5" rpy="0 0 0"/>
          <geometry>
            <cylinder length="1.1" radius="0.05"/>
          </geometry>
        </collision>
      </link>

      <joint name="elbow" type="continuous">
       <origin xyz = "0 0 -1.1" rpy="0 0 0"/>
       <parent link="upper_arm"/>
       <child link="lower_arm"/>
       <axis xyz=" 1 1 1"/>
       <dynamics damping="0.1" />
      </joint>

      <link name="lower_arm">
      <inertial>
         <origin xyz="0 0 -.5" rpy="0 0 0"/>
         <mass value="1"/>
         <inertia ixx="1"  ixy="0"  ixz="0" iyy="1" iyz="0" izz="1" />
       </inertial>

        <visual>
          <origin xyz="0 0 -.5" rpy="0 0 0"/>
          <geometry>
           <cylinder length="1.1" radius="0.05"/>
          </geometry>
        </visual>

        <collision name = "collision_upper">
          <origin xyz="0 0 -.5" rpy="0 0 0"/>
          <geometry>
            <cylinder length="1.1" radius="0.05"/>
          </geometry>
        </collision>
      </link>

   </robot>
